Workbook

Sheet Dashboard
A1: Arborescence SEO - Boutique Coloriages Kawaii
A2: Structure de site avec collections basees sur des mots-cles Ahrefs. Chaque collection = un mot-cle cible.
A4: Collections actives | B4: Volume SEO total | C4: SKU cible total | E4: KD moyen pondere | F4: CPC moyen pondere | G4: Prix moyen cible
A5: =COUNTIF(Collections!$D$4:$D$18,"Oui") | B5: =SUM(Collections!$F$4:$F$18) | C5: =SUM(Collections!$K$4:$K$18) | E5: =ROUND(SUMPRODUCT(Collections!$F$4:$F$18,Collections!$G$4:$G$18)/SUM(Collections!$F$4:$F$18),1) | F5: =ROUND(SUMPRODUCT(Collections!$F$4:$F$18,Collections!$H$4:$H$18)/SUMIF(Collections!$H$4:$H$18,">0",Collections!$F$4:$F$18),2) | G5: =ROUND(AVERAGE(Collections!$L$4:$L$18),1)
A8: Roadmap recommandee
A9: 1 | B9: Lancer les collections P1 | C9: Coloriage kawaii, adulte, magique, mystere, cosy et feutre acrylique. | D9: Objectif : capter les plus gros volumes avec des pages de collection solides et des bundles physiques.
A10: 2 | B10: Construire 300+ SKU | C10: Repartir les SKU selon SKU_Plan, en commencant par les packs et kits a forte marge. | D10: Eviter les fichiers gratuits : vendre des objets physiques, lots et personnalisations.
A11: 3 | B11: Maillage interne | C11: Chaque page P2 remonte vers coloriage kawaii et vers l'accessoire le plus logique. | D11: Ex : coloriage manga -> feutre a alcool; coloriage cosy -> marque page personnalise.
A12: 4 | B12: Contenu SEO | C12: Ajouter guides courts sur les pages collection et 8-12 articles blog top-funnel. | D12: Blog uniquement pour alimenter les collections, pas comme destination principale.
A13: 5 | B13: Sourcing | C13: Exclure les licences et personnages proteges. | D13: Utiliser des designs originaux kawaii, chibi, animaux, cocooning, football generique.
A16: Top collections a creer en premier
A17: Priorite | B17: Collection = mot-cle | C17: Volume | D17: SKU cible | E17: Pourquoi
A18: P1 | B18: coloriage kawaii | C18: 38000 | D18: 45 | E18: Page pilier et mot-cle exact-match de la marque.
A19: P1 | B19: feutre acrylique | C19: 33000 | D19: 40 | E19: Accessoire a panier moyen et marge plus forte.
A20: P1 | B20: coloriage adulte | C20: 15000 | D20: 35 | E20: Segment plus premium, bon pour bundles.
A21: P1 | B21: coloriage magique | C21: 13000 | D21: 30 | E21: Giftable enfant, bonne intention produit.
A22: P1 | B22: coloriage mystere | C22: 12000 | D22: 30 | E22: Angle ludique, retention et cross-sell.
A25: Veille concurrentielle - pure players spécialisés
A26: Concurrents qualifiés | B26: Sites français inclus | C26: Menaces hautes | D26: Faux positifs exclus
A27: =COUNTA('Concurrents'!$A$4:$A$17) | B27: =COUNTIF('Concurrents'!$C$4:$C$17,"France / français")+COUNTIF('Concurrents'!$C$4:$C$17,"France / français-anglais") | C27: =COUNTIF('Concurrents'!$M$4:$M$17,"Haute") | D27: =COUNTA('Concurrents'!$A$22:$A$32)
A29: Espace FR encore peu occupé : AICrayons et MyCuttieBox sont les plus proches localement; Belly Bean et Bobbie Goods sont les menaces internationales, Cozykleuren le meilleur modèle de catalogue.

Sheet Arborescence
A1: Arborescence de site - Coloriages Kawaii
A3: Niveau | B3: Type page | C3: Parent | D3: Collection = mot-cle | E3: URL | F3: H1 | G3: Volume FR | H3: KD | I3: CPC | J3: Intention | K3: Priorite | L3: SKU cible | M3: Role SEO | N3: Meta title | O3: Meta description | P3: Maillage interne | Q3: Notes
A4: 0 | B4: Accueil / hub marque | C4: - | D4: coloriage kawaii | E4: / | F4: Coloriage Kawaii | G4: 38000 | H4: 1 | I4: 0.06 | J4: Marque + commerciale | K4: P1 | L4: 0 | M4: Page d'entree marque, rassurance, best-sellers et collections P1. | N4: Coloriage Kawaii | Kits, carnets et feutres mignons | O4: Boutique de coloriages kawaii, carnets creatifs, feutres et kits cadeaux pour enfants et adultes. | P4: Liens directs vers toutes les collections P1 et accessoires. | Q4: Ne pas surcharger en texte : montrer les produits et bundles.
A5: 1 | B5: Hub menu non-collection | C5: / | E5: /univers/coloriage-kawaii | F5: Coloriages kawaii | J5: Navigation | M5: Regroupe les collections sans cannibaliser les mots-cles exacts. | N5: Coloriages kawaii | O5: Selection coloriages pour orienter le visiteur vers les collections. | P5: Liens vers collections du meme pilier. | Q5: Menu principal
A6: 1 | B6: Hub menu non-collection | C6: / | E6: /univers/feutre-acrylique | F6: Feutres et accessoires | J6: Navigation | M6: Regroupe les collections sans cannibaliser les mots-cles exacts. | N6: Feutres et accessoires | O6: Selection accessoires pour orienter le visiteur vers les collections. | P6: Liens vers collections du meme pilier. | Q6: Menu principal
A7: 1 | B7: Hub menu non-collection | C7: / | E7: /univers/diamond-painting-personnalise | F7: Cadeaux creatifs | J7: Navigation | M7: Regroupe les collections sans cannibaliser les mots-cles exacts. | N7: Cadeaux creatifs | O7: Selection cadeaux creatifs pour orienter le visiteur vers les collections. | P7: Liens vers collections du meme pilier. | Q7: Menu principal
A8: 2 | B8: Collection | C8: /univers/coloriages | D8: coloriage kawaii | E8: /collections/coloriage-kawaii | F8: Coloriage Kawaii | G8: 38000 | H8: 1 | I8: 0.06 | J8: Transactionnelle | K8: P1 | L8: 45 | M8: Collection pilier SEO et commerciale | N8: coloriage kawaii | Kits et carnets kawaii | O8: Découvrez notre collection coloriage kawaii : carnets, kits et accessoires créatifs pour une boutique coloriage kawaii. | P8: Depuis accueil + menu + collections P2 liees | Q8: Livres, carnets, packs imprimés, bundles découverte. Page mère à mailler vers tous les thèmes kawaii.
A9: 2 | B9: Collection | C9: /univers/coloriages | D9: coloriage adulte | E9: /collections/coloriage-adulte | F9: Coloriage Adulte | G9: 15000 | H9: 0 | I9: 0.1 | J9: Commerciale | K9: P1 | L9: 35 | M9: Segment panier plus élevé | N9: coloriage adulte | Kits et carnets kawaii | O9: Découvrez notre collection coloriage adulte : carnets, kits et accessoires créatifs pour une boutique coloriage kawaii. | P9: Depuis accueil + menu + collections P2 liees | Q9: Cahiers anti-stress, mandalas kawaii, carnets premium papier épais, packs feutres + livre.
A10: 2 | B10: Collection | C10: /univers/coloriages | D10: coloriage magique | E10: /collections/coloriage-magique | F10: Coloriage Magique | G10: 13000 | H10: 3 | I10: 0.08 | J10: Commerciale | K10: P1 | L10: 30 | M10: Collection enfant/giftable | N10: coloriage magique | Kits et carnets kawaii | O10: Découvrez notre collection coloriage magique : carnets, kits et accessoires créatifs pour une boutique coloriage kawaii. | P10: Depuis accueil + menu + collections P2 liees | Q10: Livres à révélation, feutres magiques, cahiers effaçables, packs cadeaux anniversaire.
A11: 2 | B11: Collection | C11: /univers/coloriages | D11: coloriage mystere | E11: /collections/coloriage-mystere | F11: Coloriage Mystere | G11: 12000 | H11: 0 | I11: 0.09 | J11: Transactionnelle | K11: P1 | L11: 30 | M11: Angle découverte et retention | N11: coloriage mystere | Kits et carnets kawaii | O11: Découvrez notre collection coloriage mystere : carnets, kits et accessoires créatifs pour une boutique coloriage kawaii. | P11: Depuis accueil + menu + collections P2 liees | Q11: Coloriages mystères par numéros, pixels kawaii, animaux cachés, cartes surprises.
A12: 2 | B12: Collection | C12: /univers/coloriages | D12: coloriage cosy | E12: /collections/coloriage-cosy | F12: Coloriage Cosy | G12: 9200 | H12: 0 | I12: 0.11 | J12: Commerciale | K12: P1 | L12: 30 | M12: Positionnement marque cosy | N12: coloriage cosy | Kits et carnets kawaii | O12: Découvrez notre collection coloriage cosy : carnets, kits et accessoires créatifs pour une boutique coloriage kawaii. | P12: Depuis accueil + menu + collections P2 liees | Q12: Univers cocooning : chats, thé, maison, automne, journaling, packs relaxation.
A13: 2 | B13: Collection | C13: /univers/coloriages | D13: coloriage manga | E13: /collections/coloriage-manga | F13: Coloriage Manga | G13: 7000 | H13: 0 | I13: 0.07 | J13: Commerciale | K13: P2 | L13: 25 | M13: Trafic passion mais IP-safe | N13: coloriage manga | Kits et carnets kawaii | O13: Découvrez notre collection coloriage manga : carnets, kits et accessoires créatifs pour une boutique coloriage kawaii. | P13: Depuis page pilier + recommandations produits | Q13: Personnages originaux manga/chibi, expressions, tenues, cahiers apprentissage dessin.
A14: 2 | B14: Collection | C14: /univers/coloriages | D14: coloriage foot | E14: /collections/coloriage-foot | F14: Coloriage Foot | G14: 6600 | H14: 0 | I14: 0.06 | J14: Commerciale | K14: P2 | L14: 25 | M14: Collection cadeau enfant | N14: coloriage foot | Kits et carnets kawaii | O14: Découvrez notre collection coloriage foot : carnets, kits et accessoires créatifs pour une boutique coloriage kawaii. | P14: Depuis page pilier + recommandations produits | Q14: Coloriages football génériques, maillots non licenciés, trophées, ballons, activités anniversaire.
A15: 2 | B15: Collection | C15: /univers/coloriages | D15: coloriage fille | E15: /collections/coloriage-fille | F15: Coloriage Fille | G15: 6600 | H15: 0 | J15: Commerciale | K15: P2 | L15: 25 | M15: Requête large enfant | N15: coloriage fille | Kits et carnets kawaii | O15: Découvrez notre collection coloriage fille : carnets, kits et accessoires créatifs pour une boutique coloriage kawaii. | P15: Depuis page pilier + recommandations produits | Q15: Licornes, animaux mignons, sirènes, mode, stickers. Attention à garder un wording inclusif en site.
A16: 2 | B16: Collection | C16: /univers/coloriages | D16: coloriage kawaii fille | E16: /collections/coloriage-kawaii-fille | F16: Coloriage Kawaii Fille | G16: 4800 | H16: 1 | J16: Transactionnelle | K16: P2 | L16: 25 | M16: Longue traîne transactionnelle | N16: coloriage kawaii fille | Kits et carnets kawaii | O16: Découvrez notre collection coloriage kawaii fille : carnets, kits et accessoires créatifs pour une boutique coloriage kawaii. | P16: Depuis page pilier + recommandations produits | Q16: Déclinaison plus ciblée de la page pilier, à mailler depuis coloriage kawaii et coloriage fille.
A17: 2 | B17: Collection | C17: /univers/themes-kawaii | D17: chat kawaii | E17: /collections/chat-kawaii | F17: Chat Kawaii | G17: 4200 | H17: 0 | I17: 0.06 | J17: Commerciale | K17: P2 | L17: 20 | M17: Thème très brandable | N17: chat kawaii | Kits et carnets kawaii | O17: Découvrez notre collection chat kawaii : carnets, kits et accessoires créatifs pour une boutique coloriage kawaii. | P17: Depuis page pilier + recommandations produits | Q17: Collection de livres, stickers, marque-pages et mini kits autour du chat kawaii.
A18: 2 | B18: Collection | C18: /univers/accessoires | D18: feutre acrylique | E18: /collections/feutre-acrylique | F18: Feutre Acrylique | G18: 33000 | H18: 0 | I18: 0.16 | J18: Transactionnelle | K18: P1 | L18: 40 | M18: Monétisation accessoire forte | N18: feutre acrylique | Kits et carnets kawaii | O18: Découvrez notre collection feutre acrylique : carnets, kits et accessoires créatifs pour une boutique coloriage kawaii. | P18: Depuis accueil + menu + collections P2 liees | Q18: Sets de feutres, pointes fines, packs couleurs pastel, bundle avec cahiers papier épais.
A19: 2 | B19: Collection | C19: /univers/accessoires | D19: feutre a alcool | E19: /collections/feutre-a-alcool | F19: Feutre A Alcool | G19: 5400 | H19: 0 | I19: 0.21 | J19: Transactionnelle | K19: P2 | L19: 30 | M19: Panier moyen et upsell | N19: feutre a alcool | Kits et carnets kawaii | O19: Découvrez notre collection feutre a alcool : carnets, kits et accessoires créatifs pour une boutique coloriage kawaii. | P19: Depuis page pilier + recommandations produits | Q19: Sets alcohol markers, nuanciers, pochettes rangement, packs débutant et premium.
A20: 2 | B20: Collection | C20: /univers/accessoires | D20: trousse kawaii | E20: /collections/trousse-kawaii | F20: Trousse Kawaii | G20: 3800 | H20: 0 | I20: 0.14 | J20: Transactionnelle | K20: P2 | L20: 20 | M20: Produit léger et cadeau | N20: trousse kawaii | Kits et carnets kawaii | O20: Découvrez notre collection trousse kawaii : carnets, kits et accessoires créatifs pour une boutique coloriage kawaii. | P20: Depuis page pilier + recommandations produits | Q20: Trousses mignonnes, pochettes feutres, rangement coloriage, lots rentrée.
A21: 2 | B21: Collection | C21: /univers/cadeaux-creatifs | D21: marque page personnalisé | E21: /collections/marque-page-personnalise | F21: Marque Page Personnalisé | G21: 3700 | H21: 1 | I21: 0.42 | J21: Transactionnelle | K21: P2 | L21: 20 | M21: AOV par personnalisation | N21: marque page personnalisé | Kits et carnets kawaii | O21: Découvrez notre collection marque page personnalisé : carnets, kits et accessoires créatifs pour une boutique coloriage kawaii. | P21: Depuis page pilier + recommandations produits | Q21: Marque-pages prénom, chats, fleurs, citations, lots de 3 et bundle cahier.
A22: 2 | B22: Collection | C22: /univers/cadeaux-creatifs | D22: diamond painting personnalisé | E22: /collections/diamond-painting-personnalise | F22: Diamond Painting Personnalisé | G22: 6000 | H22: 2 | I22: 0.71 | J22: Transactionnelle | K22: P2 | L22: 30 | M22: Produit cadeau à marge | N22: diamond painting personnalisé | Kits et carnets kawaii | O22: Découvrez notre collection diamond painting personnalisé : carnets, kits et accessoires créatifs pour une boutique coloriage kawaii. | P22: Depuis page pilier + recommandations produits | Q22: Kits personnalisés, formats petits faciles à expédier, modèles animaux kawaii.
A23: 1 | B23: Blog SEO | C23: / | E23: /blogs/guides | F23: Guides coloriage kawaii | J23: Informationnelle | K23: P3 | M23: Alimenter les collections, pas remplacer les pages transactionnelles. | N23: Guides coloriage kawaii | O23: Idees, conseils feutres et inspirations pour mieux colorier. | P23: Chaque article doit pointer vers une collection. | Q23: Exemples : comment choisir ses feutres, coloriage kawaii adulte, idees cadeaux.
A24: 1 | B24: Pages confiance | C24: / | E24: /pages/livraison-retours | F24: Livraison et retours | J24: Rassurance | K24: P2 | M24: Limiter la friction avant achat. | N24: Livraison et retours | O24: Delais, suivi et retours pour les kits coloriage kawaii. | P24: Footer + checkout. | Q24: Essentiel pour dropshipping : clarifier delais et suivi.

Sheet Collections
A1: Collections SEO - 1 collection = 1 mot-cle
A3: Ordre | B3: Pilier | C3: Collection = mot-cle | D3: Active | E3: URL | F3: Volume FR | G3: KD | H3: CPC | I3: Intention | J3: Priorite | K3: SKU cible | L3: Prix moyen cible | M3: Score SEO | N3: Role commercial | O3: Brief collection | P3: Source CSV keyword
A4: 1 | B4: Coloriages | C4: coloriage kawaii | D4: Oui | E4: /collections/coloriage-kawaii | F4: 38000 | G4: 1 | H4: 0.06 | I4: Transactionnelle | J4: P1 | K4: 45 | L4: 24.9 | M4: =ROUND((F4/(G4+1))*IF(J4="P1",1.2,IF(J4="P2",1,0.8)),0) | N4: Collection pilier SEO et commerciale | O4: Livres, carnets, packs imprimés, bundles découverte. Page mère à mailler vers tous les thèmes kawaii. | P4: coloriage kawaii
A5: 2 | B5: Coloriages | C5: coloriage adulte | D5: Oui | E5: /collections/coloriage-adulte | F5: 15000 | G5: 0 | H5: 0.1 | I5: Commerciale | J5: P1 | K5: 35 | L5: 29.9 | M5: =ROUND((F5/(G5+1))*IF(J5="P1",1.2,IF(J5="P2",1,0.8)),0) | N5: Segment panier plus élevé | O5: Cahiers anti-stress, mandalas kawaii, carnets premium papier épais, packs feutres + livre. | P5: coloriage adulte
A6: 3 | B6: Coloriages | C6: coloriage magique | D6: Oui | E6: /collections/coloriage-magique | F6: 13000 | G6: 3 | H6: 0.08 | I6: Commerciale | J6: P1 | K6: 30 | L6: 22.9 | M6: =ROUND((F6/(G6+1))*IF(J6="P1",1.2,IF(J6="P2",1,0.8)),0) | N6: Collection enfant/giftable | O6: Livres à révélation, feutres magiques, cahiers effaçables, packs cadeaux anniversaire. | P6: coloriage magique
A7: 4 | B7: Coloriages | C7: coloriage mystere | D7: Oui | E7: /collections/coloriage-mystere | F7: 12000 | G7: 0 | H7: 0.09 | I7: Transactionnelle | J7: P1 | K7: 30 | L7: 24.9 | M7: =ROUND((F7/(G7+1))*IF(J7="P1",1.2,IF(J7="P2",1,0.8)),0) | N7: Angle découverte et retention | O7: Coloriages mystères par numéros, pixels kawaii, animaux cachés, cartes surprises. | P7: coloriage mystere
A8: 5 | B8: Coloriages | C8: coloriage cosy | D8: Oui | E8: /collections/coloriage-cosy | F8: 9200 | G8: 0 | H8: 0.11 | I8: Commerciale | J8: P1 | K8: 30 | L8: 27.9 | M8: =ROUND((F8/(G8+1))*IF(J8="P1",1.2,IF(J8="P2",1,0.8)),0) | N8: Positionnement marque cosy | O8: Univers cocooning : chats, thé, maison, automne, journaling, packs relaxation. | P8: coloriage cosy
A9: 6 | B9: Coloriages | C9: coloriage manga | D9: Oui | E9: /collections/coloriage-manga | F9: 7000 | G9: 0 | H9: 0.07 | I9: Commerciale | J9: P2 | K9: 25 | L9: 24.9 | M9: =ROUND((F9/(G9+1))*IF(J9="P1",1.2,IF(J9="P2",1,0.8)),0) | N9: Trafic passion mais IP-safe | O9: Personnages originaux manga/chibi, expressions, tenues, cahiers apprentissage dessin. | P9: coloriage manga
A10: 7 | B10: Coloriages | C10: coloriage foot | D10: Oui | E10: /collections/coloriage-foot | F10: 6600 | G10: 0 | H10: 0.06 | I10: Commerciale | J10: P2 | K10: 25 | L10: 19.9 | M10: =ROUND((F10/(G10+1))*IF(J10="P1",1.2,IF(J10="P2",1,0.8)),0) | N10: Collection cadeau enfant | O10: Coloriages football génériques, maillots non licenciés, trophées, ballons, activités anniversaire. | P10: coloriage foot
A11: 8 | B11: Coloriages | C11: coloriage fille | D11: Oui | E11: /collections/coloriage-fille | F11: 6600 | G11: 0 | I11: Commerciale | J11: P2 | K11: 25 | L11: 19.9 | M11: =ROUND((F11/(G11+1))*IF(J11="P1",1.2,IF(J11="P2",1,0.8)),0) | N11: Requête large enfant | O11: Licornes, animaux mignons, sirènes, mode, stickers. Attention à garder un wording inclusif en site. | P11: coloriage fille
A12: 9 | B12: Coloriages | C12: coloriage kawaii fille | D12: Oui | E12: /collections/coloriage-kawaii-fille | F12: 4800 | G12: 1 | I12: Transactionnelle | J12: P2 | K12: 25 | L12: 19.9 | M12: =ROUND((F12/(G12+1))*IF(J12="P1",1.2,IF(J12="P2",1,0.8)),0) | N12: Longue traîne transactionnelle | O12: Déclinaison plus ciblée de la page pilier, à mailler depuis coloriage kawaii et coloriage fille. | P12: coloriage kawaii fille
A13: 10 | B13: Thèmes kawaii | C13: chat kawaii | D13: Oui | E13: /collections/chat-kawaii | F13: 4200 | G13: 0 | H13: 0.06 | I13: Commerciale | J13: P2 | K13: 20 | L13: 22.9 | M13: =ROUND((F13/(G13+1))*IF(J13="P1",1.2,IF(J13="P2",1,0.8)),0) | N13: Thème très brandable | O13: Collection de livres, stickers, marque-pages et mini kits autour du chat kawaii. | P13: chat kawaii
A14: 11 | B14: Accessoires | C14: feutre acrylique | D14: Oui | E14: /collections/feutre-acrylique | F14: 33000 | G14: 0 | H14: 0.16 | I14: Transactionnelle | J14: P1 | K14: 40 | L14: 29.9 | M14: =ROUND((F14/(G14+1))*IF(J14="P1",1.2,IF(J14="P2",1,0.8)),0) | N14: Monétisation accessoire forte | O14: Sets de feutres, pointes fines, packs couleurs pastel, bundle avec cahiers papier épais. | P14: feutre acrylique
A15: 12 | B15: Accessoires | C15: feutre a alcool | D15: Oui | E15: /collections/feutre-a-alcool | F15: 5400 | G15: 0 | H15: 0.21 | I15: Transactionnelle | J15: P2 | K15: 30 | L15: 34.9 | M15: =ROUND((F15/(G15+1))*IF(J15="P1",1.2,IF(J15="P2",1,0.8)),0) | N15: Panier moyen et upsell | O15: Sets alcohol markers, nuanciers, pochettes rangement, packs débutant et premium. | P15: feutre a alcool
A16: 13 | B16: Accessoires | C16: trousse kawaii | D16: Oui | E16: /collections/trousse-kawaii | F16: 3800 | G16: 0 | H16: 0.14 | I16: Transactionnelle | J16: P2 | K16: 20 | L16: 19.9 | M16: =ROUND((F16/(G16+1))*IF(J16="P1",1.2,IF(J16="P2",1,0.8)),0) | N16: Produit léger et cadeau | O16: Trousses mignonnes, pochettes feutres, rangement coloriage, lots rentrée. | P16: trousse kawaii
A17: 14 | B17: Cadeaux creatifs | C17: marque page personnalisé | D17: Oui | E17: /collections/marque-page-personnalise | F17: 3700 | G17: 1 | H17: 0.42 | I17: Transactionnelle | J17: P2 | K17: 20 | L17: 14.9 | M17: =ROUND((F17/(G17+1))*IF(J17="P1",1.2,IF(J17="P2",1,0.8)),0) | N17: AOV par personnalisation | O17: Marque-pages prénom, chats, fleurs, citations, lots de 3 et bundle cahier. | P17: marque page personnalisé
A18: 15 | B18: Cadeaux creatifs | C18: diamond painting personnalisé | D18: Oui | E18: /collections/diamond-painting-personnalise | F18: 6000 | G18: 2 | H18: 0.71 | I18: Transactionnelle | J18: P2 | K18: 30 | L18: 34.9 | M18: =ROUND((F18/(G18+1))*IF(J18="P1",1.2,IF(J18="P2",1,0.8)),0) | N18: Produit cadeau à marge | O18: Kits personnalisés, formats petits faciles à expédier, modèles animaux kawaii. | P18: diamond painting personnalisé

Sheet SKU_Plan
A1: Plan SKU - 300+ produits sans sortir du theme
A3: Collection = mot-cle | B3: Pilier | C3: SKU cible | D3: Prix moyen cible | E3: Repartition SKU | F3: Exemples produits | G3: Bundle prioritaire | H3: Recherche sourcing AliExpress | I3: Priorite | J3: Risque a eviter
A4: coloriage kawaii | B4: Coloriages | C4: 45 | D4: 24.9 | E4: 15 livres thématiques, 10 carnets, 10 packs pages, 5 bundles feutres, 5 éditions cadeau | F4: Livres, carnets, packs imprimés, bundles découverte. Page mère à mailler vers tous les thèmes kawaii. | G4: Bundle coloriage kawaii + feutres + marque-page | H4: kawaii coloring book, cute coloring pages book, kids coloring book bundle | I4: P1 | J4: Verifier qualite papier, delais, packaging et photos fournisseurs.
A5: coloriage adulte | B5: Coloriages | C5: 35 | D5: 29.9 | E5: 12 livres premium, 8 mandalas kawaii, 6 kits relaxation, 5 carnets papier épais, 4 bundles | F5: Cahiers anti-stress, mandalas kawaii, carnets premium papier épais, packs feutres + livre. | G5: Bundle coloriage adulte + feutres + marque-page | H5: adult coloring book, stress relief coloring book, cute mandala coloring | I5: P1 | J5: Verifier qualite papier, delais, packaging et photos fournisseurs.
A6: coloriage magique | B6: Coloriages | C6: 30 | D6: 22.9 | E6: 10 livres eau, 8 feutres magiques, 6 cahiers réutilisables, 4 sets anniversaire, 2 packs voyage | F6: Livres à révélation, feutres magiques, cahiers effaçables, packs cadeaux anniversaire. | G6: Bundle coloriage magique + feutres + marque-page | H6: magic coloring book, reusable coloring book, water coloring book | I6: P1 | J6: Verifier qualite papier, delais, packaging et photos fournisseurs.
A7: coloriage mystere | B7: Coloriages | C7: 30 | D7: 24.9 | E7: 10 livres par numéros, 8 pixel art, 6 cartes mystère, 4 packs animaux, 2 mini formats | F7: Coloriages mystères par numéros, pixels kawaii, animaux cachés, cartes surprises. | G7: Bundle coloriage mystere + feutres + marque-page | H7: mystery coloring book, color by number cute, pixel coloring book | I7: P1 | J7: Verifier qualite papier, delais, packaging et photos fournisseurs.
A8: coloriage cosy | B8: Coloriages | C8: 30 | D8: 27.9 | E8: 10 livres cocooning, 6 automne, 5 chats, 5 cottagecore, 4 bundles détente | F8: Univers cocooning : chats, thé, maison, automne, journaling, packs relaxation. | G8: Bundle coloriage cosy + feutres + marque-page | H8: cozy coloring book, cottagecore coloring book, cute home coloring | I8: P1 | J8: Verifier qualite papier, delais, packaging et photos fournisseurs.
A9: coloriage manga | B9: Coloriages | C9: 25 | D9: 24.9 | E9: 8 chibi, 6 personnages originaux, 5 expressions, 4 tenues, 2 apprentissage dessin | F9: Personnages originaux manga/chibi, expressions, tenues, cahiers apprentissage dessin. | G9: Bundle coloriage manga + feutres + marque-page | H9: manga coloring book, chibi coloring book, anime style coloring book | I9: P2 | J9: Eviter personnages sous licence et visuels copies.
A10: coloriage foot | B10: Coloriages | C10: 25 | D10: 19.9 | E10: 8 cahiers football, 6 packs anniversaire, 5 ballons/trophées, 4 mini livres, 2 stickers | F10: Coloriages football génériques, maillots non licenciés, trophées, ballons, activités anniversaire. | G10: Bundle coloriage foot + feutres + marque-page | H10: football coloring book, soccer coloring pages book, sports coloring book | I10: P2 | J10: Verifier qualite papier, delais, packaging et photos fournisseurs.
A11: coloriage fille | B11: Coloriages | C11: 25 | D11: 19.9 | E11: 8 licornes, 6 animaux, 5 sirènes, 4 mode, 2 packs stickers | F11: Licornes, animaux mignons, sirènes, mode, stickers. Attention à garder un wording inclusif en site. | G11: Bundle coloriage fille + feutres + marque-page | H11: girls coloring book, unicorn coloring book, cute animals coloring | I11: P2 | J11: Verifier qualite papier, delais, packaging et photos fournisseurs.
A12: coloriage kawaii fille | B12: Coloriages | C12: 25 | D12: 19.9 | E12: 8 livres kawaii, 6 animaux, 5 sirènes/licornes, 4 mini carnets, 2 bundles | F12: Déclinaison plus ciblée de la page pilier, à mailler depuis coloriage kawaii et coloriage fille. | G12: Bundle coloriage kawaii fille + feutres + marque-page | H12: kawaii girl coloring book, cute coloring book girl, kawaii activity book | I12: P2 | J12: Verifier qualite papier, delais, packaging et photos fournisseurs.
A13: chat kawaii | B13: Thèmes kawaii | C13: 20 | D13: 22.9 | E13: 8 livres chats, 4 stickers, 4 marque-pages, 2 cartes, 2 mini carnets | F13: Collection de livres, stickers, marque-pages et mini kits autour du chat kawaii. | G13: Bundle chat kawaii + feutres + marque-page | H13: kawaii cat coloring book, cute cat stationery, cat sticker book | I13: P2 | J13: Eviter personnages sous licence et visuels copies.
A14: feutre acrylique | B14: Accessoires | C14: 40 | D14: 29.9 | E14: 12 sets pastel, 8 pointes fines, 6 double pointe, 6 kits surfaces, 8 bundles | F14: Sets de feutres, pointes fines, packs couleurs pastel, bundle avec cahiers papier épais. | G14: Bundle feutre acrylique + coloriage kawaii | H14: acrylic markers set pastel, acrylic paint pens, dual tip acrylic markers | I14: P1 | J14: Verifier qualite papier, delais, packaging et photos fournisseurs.
A15: feutre a alcool | B15: Accessoires | C15: 30 | D15: 34.9 | E15: 10 sets débutant, 8 sets premium, 5 nuanciers, 4 pochettes, 3 bundles livre | F15: Sets alcohol markers, nuanciers, pochettes rangement, packs débutant et premium. | G15: Bundle feutre a alcool + coloriage kawaii | H15: alcohol markers set, dual tip alcohol marker, marker storage case | I15: P2 | J15: Verifier qualite papier, delais, packaging et photos fournisseurs.
... A18: diamond painting personnalisé | B18: Cadeaux creatifs | C18: 30 | D18: 34.9 | E18: 10 formats portrait, 6 animaux, 5 mini kits, 5 packs cadeau, 4 accessoires | F18: Kits personnalisés, formats petits faciles à expédier, modèles animaux kawaii. | G18: Bundle diamond painting personnalisé + feutres + marque-page | H18: custom diamond painting kit, personalized diamond painting, small diamond art kit | I18: P2 | J18: Verifier qualite papier, delais, packaging et photos fournisseurs.

Sheet Concurrents
A1: Concurrents spécialisés - coloriage kawaii et cosy
A2: Pure players et mini-marques vérifiés le 2026-07-10. Marketplaces, grandes enseignes et sites sans vente directe sont exclus.
A3: Concurrent | B3: URL | C3: Pays / langue | D3: Livraison France | E3: Positionnement | F3: Spécialisation | G3: Prix repère | H3: Maturité visible | I3: Forces | J3: Faiblesses | K3: Opportunité pour la boutique | L3: URL de preuve | M3: Menace FR | N3: Date vérification
A4: AICrayons | B4: https://aicrayons.fr/ | C4: France / français | D4: Oui - acteur local | E4: Carnets physiques et PDF kawaii, chibi, cosy, fantasy et grayscale. | F4: Très proche | G4: 13,90 EUR le carnet spiralé observé | H4: Catalogue étoffé, CGV et retours structurés; peu d'avis visibles. | I4: Livraison locale, physique + numérique, papier 120 g, prix accessible. | J4: Univers graphique dispersé et peu incarné. | K4: Construire une marque kawaii cohérente avec mascottes et preuves de qualité. | L4: https://aicrayons.fr/produit/carnet-a-spirale-les-zanimaux-kawaii/ | M4: Haute | N4: 2026-07-10
A5: MyCuttieBox | B5: https://mycuttiebox.fr/ | C5: France / français | D5: Oui - acteur local | E5: Box cosy avec carnet, marqueur blanc, bougie, stickers et bijou de sac. | F5: Concept extrêmement proche | G5: 24,90-29,90 EUR la box | H5: Première édition en précommande; bonus limité aux premières commandes. | I5: Concept cadeau, panier moyen supérieur, mascottes et illustrations propriétaires. | J5: Faible profondeur de catalogue, logistique de box, offre encore saisonnière. | K5: Déployer des collections permanentes et des kits personnalisables. | L5: https://mycuttiebox.fr/precommande/product-box-cosy-page | M5: Haute | N5: 2026-07-10
A6: Nippon Kawaii | B6: https://www.nipponkawaii.nl/en/ | C6: Pays-Bas / NL-EN-DE | D6: Oui - expédition UE | E6: Boutique kawaii avec livres cosy, peluches, papeterie et accessoires. | F6: Proche - coloriage secondaire | G6: Livraison France affichée à partir de 9,99 EUR | H6: Depuis 2016, 540+ avis et note annoncée de 9,8/10. | I6: Confiance, stock UE, licences officielles, expédition rapide et cross-sell. | J6: Peu de livres cosy, ruptures et aucune localisation française. | K6: Proposer plus de profondeur, du SEO français et des bundles spécialisés. | L6: https://www.nipponkawaii.nl/en/collections/cozy-coloring-books-1 | M6: Moyenne | N6: 2026-07-10
A7: Cozykleuren.nl | B7: https://cozykleuren.nl/ | C7: Pays-Bas / néerlandais | D7: France sélectionnable; tarif à confirmer | E7: Livres cosy, marqueurs alcool, crayons et accessoires de protection. | F7: Coloriage pur | G7: N/D pour la France | H7: Équipe de quatre, entrepôt, société et TVA affichés. | I7: Arborescence aboutie, assortiment livres + consommables, hausse de panier. | J7: Pas de français, livraison France peu claire et ruptures visibles. | K7: Répliquer le modèle catalogue en version française avec stock fiable. | L7: https://cozykleuren.nl/pages/over-ons | M7: Moyenne | N7: 2026-07-10
A8: Bobbie Goods | B8: https://bobbiegoods.com/ | C8: États-Unis / anglais | D8: Oui - international | E8: Livres premium et accessoires autour de personnages propriétaires. | F8: Pur cute/cozy coloring | G8: 22 USD le livre observé | H8: Marque familiale depuis 2021; une référence à 584 avis, 98% positifs. | I8: Univers reconnaissable, rareté, papier épais et communauté forte. | J8: Frais, douane et délais internationaux; peu de pages par livre. | K8: Qualité comparable avec stock UE et prix livré inférieur. | L8: https://bobbiegoods.com/products/this-n-that-coloring-book | M8: Moyenne | N8: 2026-07-10
A9: Belly Bean Co. | B9: https://bellybeanco.com/ | C9: Canada / anglais + éditions françaises | D9: Oui - international | E9: Livres physiques et PDF cute/cozy, éditions françaises et livres techniques. | F9: Pur cute/cozy coloring | G9: 12-29 CAD; éditions françaises autour de 16 CAD | H9: Catalogue profond, collaboration éditoriale et présence sur cinq réseaux. | I9: Éditions françaises, papier premium, thèmes et formats variés. | J9: Expédition canadienne coûteuse et quelques affichages produit confus. | K9: Faire mieux sur le coût rendu, le stock UE et la clarté du catalogue. | L9: https://bellybeanco.com/ | M9: Haute | N9: 2026-07-10
A10: Chloe & Maisy Co. | B10: https://chloeandmaisy.com/ | C10: États-Unis / anglais | D10: Oui - livraison mondiale annoncée | E10: Livres et PDF autour de deux personnages propriétaires, plus protège-pages. | F10: Pur cute/cozy coloring | G10: 22,99 USD le livre; bundle autour de 62,99 USD | H10: Environ 120 avis visibles, galerie clients et vente exclusivement directe. | I10: Personnages propriétaires, papier premium et storytelling fort. | J10: Catalogue étroit, anglais et droits de douane potentiels. | K10: Créer un univers propriétaire francophone avec davantage de collections. | L10: https://chloeandmaisy.com/pages/faq | M10: Moyenne | N10: 2026-07-10
A11: Giggles & Grace Books | B11: https://www.gigglesandgracebooks.com/ | C11: États-Unis / anglais | D11: Oui - livraison mondiale annoncée | E11: 25+ éditions revendiquées, livres physiques, PDF, personnalisation et B2B. | F11: Coloriage pur | G11: 7,99-12,99 USD physique; 1,99-2,99 USD PDF | H11: Catalogue profond, portail wholesale et papier 120 g. | I11: Prix, profondeur, personnalisation et offre professionnelle. | J11: Quelques incohérences visibles dans les chiffres marketing et les avis. | K11: Combiner profondeur catalogue et preuves de confiance plus solides. | L11: https://www.gigglesandgracebooks.com/ | M11: Moyenne | N11: 2026-07-10
A12: Amélie's Workshop | B12: https://ameliesworkshop.fr/en | C12: France / français-anglais | D12: Oui - expédition locale | E12: Livres kawaii/cozy sur le Japon, stickers, marque-pages et carnets. | F12: Proche - papeterie élargie | G12: 9,95-18 EUR les livres observés | H12: Entreprise indépendante depuis 2017, expédition annoncée en 3-4 jours. | I12: Univers d'illustratrice, collections saisonnières et logistique locale. | J12: Le catalogue de papeterie dilue la spécialisation coloriage. | K12: Être plus profond sur le coloriage et structurer les thèmes en collections SEO. | L12: https://ameliesworkshop.fr/en | M12: Moyenne | N12: 2026-07-10
A13: Whimsy Tales | B13: https://whimsytales.com/ | C13: Indonésie/Canada / anglais | D13: Numérique; pas de physique sur le site | E13: Références numériques kawaii/fantasy, blog SEO, échantillons et newsletter. | F13: Proche - numérique | G13: 7-18 CAD sur les références observées | H13: Environ 19 références et narration de marque structurée. | I13: Illustrations originales, contenu organique et acquisition par échantillons. | J13: Aucun produit physique expédié depuis le domaine. | K13: Occuper le physique et les bundles tout en gardant une stratégie de contenu. | L13: https://whimsytales.com/policies/shipping-policy | M13: Faible | N13: 2026-07-10
A14: Bloom & Bolt | B14: https://bloomandboltcoloring.com/ | C14: États-Unis probable / anglais | D14: Oui - international au checkout | E14: Livres spiralés premium, PDF, bundles et pinces de maintien. | F14: Pur cozy coloring | G14: 22,99-24,99 USD physique; 5 USD PDF | H14: Marque émergente, cinq livres physiques, six numériques et peu d'avis. | I14: Papier épais, reliure à plat, accessoires utiles et bundles. | J14: Prix livré élevé pour la France et preuve sociale faible. | K14: Reprendre les bénéfices d'usage avec une livraison européenne. | L14: https://bloomandboltcoloring.com/pages/faq | M14: Faible | N14: 2026-07-10
... A17: Kawaii Sprouts | B17: https://www.kawaiisprouts.com/ | C17: Pays non affiché / anglais | D17: Expédition mondiale annoncée | E17: Personnages originaux, livre principal et petits packs numériques. | F17: Kawaii pur | G17: 2,99-5,99 USD sur les petits packs | H17: Très petite marque, catalogue court et peu de signaux de vente. | I17: Personnages propriétaires et prix d'entrée faible. | J17: Offre physique/PDF parfois ambiguë et expérience encore artisanale. | K17: Plus de transparence, fiches françaises et marque plus professionnelle. | L17: https://www.kawaiisprouts.com/products/kawaii-sprout-50-page-coloring-book | M17: Faible | N17: 2026-07-10
A20: Faux positifs exclus
A21: Site | B21: URL | C21: Motif d'exclusion
A22: Coco Wyo | B22: https://cocowyo.com/pages/faq | C22: Le site officiel renvoie vers Amazon, Etsy ou TikTok Shop; pas de boutique DTC comparable.
A23: Didi Plums | B23: https://www.didiplums.com/paperbacks/cozy-worlds | C23: Les fiches observées renvoient vers Amazon pour l'achat.
A24: Colored Caramel | B24: https://www.coloredcaramel.com/about/ | C24: Catalogue servant de passerelle vers des marketplaces.
A25: Kiki Coloring Studio | B25: https://www.kikicoloringstudio.nl/ | C25: Micro-boutique pertinente mais vente directe limitée aux Pays-Bas.
A26: The Blue Lemon Studio | B26: https://www.thebluelemonstudio.com/ | C26: Achat via Amazon et univers davantage architectural que kawaii.
A27: Aiko Miku | B27: https://aikomiku.de/ | C27: Créatrice kawaii/chibi mais ventes identifiées via Amazon.
A28: OMY | B28: https://omy-maison.com/ | C28: Marque de loisirs créatifs trop généraliste pour le périmètre mini-marque spécialisée.
A29: Vivi Tinta | B29: https://www.vivitinta.com/pages/fqas | C29: Le site officiel indique que les achats passent par Amazon.
A30: Willa Grimshaw | B30: https://willagrimshaw.com/ | C30: Site vitrine conduisant vers Amazon ou Etsy.
A31: Selifu | B31: https://selifu.com/ | C31: Site vitrine conduisant vers Amazon ou Etsy.
A32: Southern Lotus | B32: https://www.southernlotus.com/en/shipping-policy | C32: Boutique directe pertinente mais livraison France non confirmée.

Sheet Sourcing_AliExpress
A1: Sourcing AliExpress - 5 produits à vérifier par collection
A2: 75 emplacements préparés. Les URL et métriques restent vides tant qu'elles ne proviennent pas d'un export AliExpress/DSers ou d'une liste de liens vérifiable.
A3: ID | B3: Collection | C3: Produit | D3: URL AliExpress | E3: Prix produit EUR | F3: Livraison EUR | G3: Coût rendu EUR | H3: Prix cible EUR | I3: Marge x | J3: Note | K3: Commandes | L3: Boutique | M3: Délai France | N3: Choice / UE | O3: Variantes / lot | P3: Angle commercial | Q3: Risques / contrôles | R3: Verdict | S3: Date vérification | T3: Statut / source | U3: Prompts images (carrousel x5) | V3: Dossier images (base PNG) | W3: Titre SEO | X3: Meta title | Y3: Meta description | Z3: Description AIDA (HTML)
A4: coloriage-kawaii-1 | B4: coloriage kawaii | C4: Livre de coloriage magique à l'eau (enfant) | D4: https://fr.aliexpress.com/item/1005006861918127.html | E4: 4.19 | F4: 0 | G4: =IF(OR(E4="",F4=""),"",E4+F4) | H4: =IFERROR(VLOOKUP(B4,'Collections'!$C$4:$L$18,10,FALSE),"") | I4: =IFERROR(H4/G4,"") | J4: 4.9 | K4: 10000 | L4: Choice — vendeur agrégé (non nominatif) | M4: 16-19 juil. (~6-9 j) | N4: Choice | O4: 1pc pen random (livre magique à l'eau) | P4: Coloriage à l'eau réutilisable & sans tache — cadeau enfant / voyage | Q4: JOUET ENFANT : conformité CE/EN71 + GPSR requise ; avertissement suffocation (petites pièces, <3 ans) ; exiger docs conformité fournisseur. Visuels génériques (OK licence). | R4: Retenir | S4: 46213 | T4: AliExpress Choice ; prix Deal du Jour (base 4,21€) ; livraison gratuite dès 10€ d'achat ; note agrégée multi-vendeurs ; JOUET CE/EN71/GPSR a valider avant lancement | U4: PACKSHOT — E-commerce hero packshot of the coloring book «Livre de coloriage magique à l'eau (enfant)», cover facing forward, centered on a clean seamless pastel background, soft studio shadow, ultra-sharp, soft pastel kawaii brand aesthetic, cohesive palette (blush pink, cream, mint, lilac), 1:1 square. LIFESTYLE — Top-down flat-lay of «Livre de coloriage magique à l'eau (enfant)» on a cozy pastel desk with colored pencils, a warm drink and a small plush, soft natural morning light, hygge kawaii mood, soft pastel kawaii brand aesthetic, cohesive palette (blush pink, cream, mint, lilac), 1:1. EN SITUATION — Close-up of a person's hands coloring a kawaii page from «Livre de coloriage magique à l'eau (enfant)», cozy blanket, shallow depth of field, warm soft tones. DÉTAIL — Macro of the open inner pages of «Livre de coloriage magique à l'eau (enfant)» showing cute kawaii line-art illustrations, crisp lines, shallow depth of field. FEATURE — Clean product feature image of «Livre de coloriage magique à l'eau (enfant)» standing upright with minimal text callouts (page count, thick paper, anti-stress), soft pastel kawaii brand aesthetic, cohesive palette (blush pink, cream, mint, lilac), generous negative space for headline. | V4: .../outputs/coloriage-kawaii-arborescence-2026-07-09/images_produits/04_coloriage-kawaii_1005006861918127 | W4: Coloriage kawaii magique à l'eau (enfant) | [Marque] | X4: magique à l'eau (enfant) — coloriage kawaii | [Marque] | Y4: magique à l'eau (enfant) : détente kawaii, illustrations mignonnes. Livraison rapide, avis vérifiés. Commandez sur [Marque] ! | Z4: <div class="product-desc"> <p>Coloriage kawaii <strong>« magique à l'eau (enfant) »</strong> — détente kawaii, illustrations mignonnes.</p> <p><strong>Envie de déconnecter et de vous détendre un crayon à la main ?</strong></p> <h3>✅ Une vraie parenthèse détente</h3> <p>Ce livre de kawaii aide à relâcher la pression : on se concentre sur les couleurs, le mental se pose. Idéal le soir ou le week-end.</p> <h3>✅ Des illustrations originales et mignonnes</h3> <p>Des pages au style kawaii, pensées pour être agréables à colorier du premier au dernier trait, sans motif trop chargé.</p> <h3>✅ Le cadeau qui fait toujours plaisir</h3> <p>Pour soi ou à offrir : un objet doux, accessible et personnel qui plaît aux ados comme aux adultes.</p> <h3>📦 Caractéristiques</h3> <ul> <li><strong>Type :</strong> Livre de coloriage broché</li> <li><strong>Pages :</strong> ≈ 24-30 pages</li> <li><strong>Papier :</strong> Épais, adapté aux feutres et crayons</li> <li><strong>Format :</strong> Compact, transportable</li> <li><strong>Contenu :</strong> 1 livre de coloriage</li> </ul> <h3>❓ Questions fréquentes</h3> <details><summary>Le papier bave-t-il avec les feutres ?</summary><p>Le papier est épais ; pour les feutres à alcool, glissez une feuille sous la page en cours par précaution.</p></details> <details><summary>Convient-il aux débutants ?</summary><p>Oui, les motifs sont accessibles : aucune technique requise, juste l'envie de colorier.</p></details> <details><summary>Y a-t-il du texte à l'intérieur ?</summary><p>Ce sont des pages à colorier ; le texte est minimal, l'univers est visuel.</p></details> <p><strong>🛒 Offrez-vous cette pause — Livraison offerte dès 39€ d'achat.</strong></p> </div>
A5: coloriage-kawaii-2 | B5: coloriage kawaii | C5: Livre de coloriage Cozy Japan (adulte, 28 p.) | D5: https://fr.aliexpress.com/item/1005009045159652.html | E5: 8.69 | F5: 0 | G5: =IF(OR(E5="",F5=""),"",E5+F5) | H5: =IFERROR(VLOOKUP(B5,'Collections'!$C$4:$L$18,10,FALSE),"") | I5: =IFERROR(H5/G5,"") | J5: 4.9 | K5: 5000 | L5: Choice — vendeur agrégé | M5: 16-19 juil. (~6-9 j) | N5: Choice | O5: Couleur Rose (28 pages) | P5: Coloriage anti-stress esthétique japonaise cozy — cadeau détente | Q5: Livre papier, visuels génériques (OK licence). Vérifier texte intérieur minimal (langue). Marge unité x2,9 (<x3), x3,4 en lot ≥2. | R5: Retenir | S5: 46213 | T5: AliExpress Choice ; livraison gratuite dès 10€ ; 1119 avis ; note agrégée | U5: PACKSHOT — E-commerce hero packshot of the coloring book «Livre de coloriage Cozy Japan (adulte, 28 p.)», cover facing forward, centered on a clean seamless pastel background, soft studio shadow, ultra-sharp, soft pastel kawaii brand aesthetic, cohesive palette (blush pink, cream, mint, lilac), 1:1 square. LIFESTYLE — Top-down flat-lay of «Livre de coloriage Cozy Japan (adulte, 28 p.)» on a cozy pastel desk with colored pencils, a warm drink and a small plush, soft natural morning light, hygge kawaii mood, soft pastel kawaii brand aesthetic, cohesive palette (blush pink, cream, mint, lilac), 1:1. EN SITUATION — Close-up of a person's hands coloring a kawaii page from «Livre de coloriage Cozy Japan (adulte, 28 p.)», cozy blanket, shallow depth of field, warm soft tones. DÉTAIL — Macro of the open inner pages of «Livre de coloriage Cozy Japan (adulte, 28 p.)» showing cute kawaii line-art illustrations, crisp lines, shallow depth of field. FEATURE — Clean product feature image of «Livre de coloriage Cozy Japan (adulte, 28 p.)» standing upright with minimal text callouts (page count, thick paper, anti-stress), soft pastel kawaii brand aesthetic, cohesive palette (blush pink, cream, mint, lilac), generous negative space for headline. | V5: .../outputs/coloriage-kawaii-arborescence-2026-07-09/images_produits/05_coloriage-kawaii_1005009045159652 | W5: Coloriage kawaii Cozy Japan (adulte, 28 p.) | [Marque] | X5: Cozy Japan (adulte, 28 p.) — coloriage kawaii | [Marque] | Y5: Cozy Japan (adulte, 28 p.) : détente kawaii, illustrations mignonnes. Livraison rapide, avis vérifiés. Commandez sur [Marque] ! | Z5: <div class="product-desc"> <p>Coloriage kawaii <strong>« Cozy Japan (adulte, 28 p.) »</strong> — détente kawaii, illustrations mignonnes.</p> <p><strong>Et si 15 minutes de coloriage remplaçaient le scroll du soir ?</strong></p> <h3>✅ Une vraie parenthèse détente</h3> <p>Ce livre de kawaii aide à relâcher la pression : on se concentre sur les couleurs, le mental se pose. Idéal le soir ou le week-end.</p> <h3>✅ Des illustrations originales et mignonnes</h3> <p>Des pages au style kawaii, pensées pour être agréables à colorier du premier au dernier trait, sans motif trop chargé.</p> <h3>✅ Le cadeau qui fait toujours plaisir</h3> <p>Pour soi ou à offrir : un objet doux, accessible et personnel qui plaît aux ados comme aux adultes.</p> <h3>📦 Caractéristiques</h3> <ul> <li><strong>Type :</strong> Livre de coloriage broché</li> <li><strong>Pages :</strong> 28 pages</li> <li><strong>Papier :</strong> Épais, adapté aux feutres et crayons</li> <li><strong>Format :</strong> Compact, transportable</li> <li><strong>Contenu :</strong> 1 livre de coloriage</li> </ul> <h3>❓ Questions fréquentes</h3> <details><summary>Le papier bave-t-il avec les feutres ?</summary><p>Le papier est épais ; pour les feutres à alcool, glissez une feuille sous la page en cours par précaution.</p></details> <details><summary>Convient-il aux débutants ?</summary><p>Oui, les motifs sont accessibles : aucune technique requise, juste l'envie de colorier.</p></details> <details><summary>Y a-t-il du texte à l'intérieur ?</summary><p>Ce sont des pages à colorier ; le texte est minimal, l'univers est visuel.</p></details> <p><strong>🛒 Offrez-vous cette pause — Livraison offerte dès 39€ d'achat.</strong></p> </div>
A6: coloriage-kawaii-3 | B6: coloriage kawaii | C6: Livre aquarelle portable 12 feuilles + pinceau | D6: https://fr.aliexpress.com/item/1005006863919029.html | E6: 4.59 | F6: 0 | G6: =IF(OR(E6="",F6=""),"",E6+F6) | H6: =IFERROR(VLOOKUP(B6,'Collections'!$C$4:$L$18,10,FALSE),"") | I6: =IFERROR(H6/G6,"") | J6: 4.9 | K6: 5000 | L6: Choice — vendeur agrégé | M6: 13-25 juil. (~3-15 j) | N6: Choice | O6: Fairytale Dreams (8 thèmes fantasy) | P6: Aquarelle nomade tout-en-un, 8 univers — enfants / débutants | Q6: Livre papier + pinceau + pastilles aquarelle : vérifier REACH pigments (contact enfant). Visuels génériques (OK). Délai jusqu'à ~15 j. | R6: Retenir | S6: 46213 | T6: AliExpress Choice ; prix Deal du Jour (base 4,61€) ; livraison gratuite dès 10€ ; 635 avis | U6: PACKSHOT — E-commerce hero packshot of the coloring book «Livre aquarelle portable 12 feuilles + pinceau», cover facing forward, centered on a clean seamless pastel background, soft studio shadow, ultra-sharp, soft pastel kawaii brand aesthetic, cohesive palette (blush pink, cream, mint, lilac), 1:1 square. LIFESTYLE — Top-down flat-lay of «Livre aquarelle portable 12 feuilles + pinceau» on a cozy pastel desk with colored pencils, a warm drink and a small plush, soft natural morning light, hygge kawaii mood, soft pastel kawaii brand aesthetic, cohesive palette (blush pink, cream, mint, lilac), 1:1. EN SITUATION — Close-up of a person's hands coloring a kawaii page from «Livre aquarelle portable 12 feuilles + pinceau», cozy blanket, shallow depth of field, warm soft tones. DÉTAIL — Macro of the open inner pages of «Livre aquarelle portable 12 feuilles + pinceau» showing cute kawaii line-art illustrations, crisp lines, shallow depth of field. FEATURE — Clean product feature image of «Livre aquarelle portable 12 feuilles + pinceau» standing upright with minimal text callouts (page count, thick paper, anti-stress), soft pastel kawaii brand aesthetic, cohesive palette (blush pink, cream, mint, lilac), generous negative space for headline. | V6: .../outputs/coloriage-kawaii-arborescence-2026-07-09/images_produits/06_coloriage-kawaii_1005006863919029 | W6: Coloriage kawaii aquarelle portable 12 feuilles + pinceau | [Marque] | X6: aquarelle portable 12 feuilles + pinceau — coloriage kawaii | Y6: aquarelle portable 12 feuilles + pinceau : détente kawaii, illustrations mignonnes. Livraison rapide, avis vérifiés. Commandez sur [Marque] ! | Z6: <div class="product-desc"> <p>Coloriage kawaii <strong>« aquarelle portable 12 feuilles + pinceau »</strong> — détente kawaii, illustrations mignonnes.</p> <p><strong>Besoin d'une pause créative, loin des écrans ?</strong></p> <h3>✅ Une vraie parenthèse détente</h3> <p>Ce livre de kawaii aide à relâcher la pression : on se concentre sur les couleurs, le mental se pose. Idéal le soir ou le week-end.</p> <h3>✅ Des illustrations originales et mignonnes</h3> <p>Des pages au style kawaii, pensées pour être agréables à colorier du premier au dernier trait, sans motif trop chargé.</p> <h3>✅ Le cadeau qui fait toujours plaisir</h3> <p>Pour soi ou à offrir : un objet doux, accessible et personnel qui plaît aux ados comme aux adultes.</p> <h3>📦 Caractéristiques</h3> <ul> <li><strong>Type :</strong> Livre de coloriage broché</li> <li><strong>Pages :</strong> ≈ 24-30 pages</li> <li><strong>Papier :</strong> Épais, adapté aux feutres et crayons</li> <li><strong>Format :</strong> Compact, transportable</li> <li><strong>Contenu :</strong> 1 livre de coloriage</li> </ul> <h3>❓ Questions fréquentes</h3> <details><summary>Le papier bave-t-il avec les feutres ?</summary><p>Le papier est épais ; pour les feutres à alcool, glissez une feuille sous la page en cours par précaution.</p></details> <details><summary>Convient-il aux débutants ?</summary><p>Oui, les motifs sont accessibles : aucune technique requise, juste l'envie de colorier.</p></details> <details><summary>Y a-t-il du texte à l'intérieur ?</summary><p>Ce sont des pages à colorier ; le texte est minimal, l'univers est visuel.</p></details> <p><strong>🛒 Offrez-vous cette pause — Livraison offerte dès 39€ d'achat.</strong></p> </div>
A7: coloriage-kawaii-4 | B7: coloriage kawaii | C7: Livre de coloriage Cozy Europe (adulte, 28 p.) | D7: https://fr.aliexpress.com/item/1005010439423261.html | E7: 7.59 | F7: 0 | G7: =IF(OR(E7="",F7=""),"",E7+F7) | H7: =IFERROR(VLOOKUP(B7,'Collections'!$C$4:$L$18,10,FALSE),"") | I7: =IFERROR(H7/G7,"") | J7: 4.9 | K7: 5000 | L7: Choice — vendeur agrégé | M7: 16-19 juil. (~6-9 j) | N7: Choice | O7: Style 8 (28 pages) | P7: Coloriage cozy adulte, scènes européennes mignonnes — détente / cadeau | Q7: Livre papier, visuels génériques (OK licence). Vérifier texte intérieur minimal. Marge x3,3. | R7: Retenir | S7: 46213 | T7: AliExpress Choice ; livraison gratuite dès 10€ ; 733 avis ; note agrégée | U7: PACKSHOT — E-commerce hero packshot of the coloring book «Livre de coloriage Cozy Europe (adulte, 28 p.)», cover facing forward, centered on a clean seamless pastel background, soft studio shadow, ultra-sharp, soft pastel kawaii brand aesthetic, cohesive palette (blush pink, cream, mint, lilac), 1:1 square. LIFESTYLE — Top-down flat-lay of «Livre de coloriage Cozy Europe (adulte, 28 p.)» on a cozy pastel desk with colored pencils, a warm drink and a small plush, soft natural morning light, hygge kawaii mood, soft pastel kawaii brand aesthetic, cohesive palette (blush pink, cream, mint, lilac), 1:1. EN SITUATION — Close-up of a person's hands coloring a kawaii page from «Livre de coloriage Cozy Europe (adulte, 28 p.)», cozy blanket, shallow depth of field, warm soft tones. DÉTAIL — Macro of the open inner pages of «Livre de coloriage Cozy Europe (adulte, 28 p.)» showing cute kawaii line-art illustrations, crisp lines, shallow depth of field. FEATURE — Clean product feature image of «Livre de coloriage Cozy Europe (adulte, 28 p.)» standing upright with minimal text callouts (page count, thick paper, anti-stress), soft pastel kawaii brand aesthetic, cohesive palette (blush pink, cream, mint, lilac), generous negative space for headline. | V7: .../outputs/coloriage-kawaii-arborescence-2026-07-09/images_produits/07_coloriage-kawaii_1005010439423261 | W7: Coloriage kawaii Cozy Europe (adulte, 28 p.) | [Marque] | X7: Cozy Europe (adulte, 28 p.) — coloriage kawaii | [Marque] | Y7: Cozy Europe (adulte, 28 p.) : détente kawaii, illustrations mignonnes. Livraison rapide, avis vérifiés. Commandez sur [Marque] ! | Z7: <div class="product-desc"> <p>Coloriage kawaii <strong>« Cozy Europe (adulte, 28 p.) »</strong> — détente kawaii, illustrations mignonnes.</p> <p><strong>Envie de déconnecter et de vous détendre un crayon à la main ?</strong></p> <h3>✅ Une vraie parenthèse détente</h3> <p>Ce livre de kawaii aide à relâcher la pression : on se concentre sur les couleurs, le mental se pose. Idéal le soir ou le week-end.</p> <h3>✅ Des illustrations originales et mignonnes</h3> <p>Des pages au style kawaii, pensées pour être agréables à colorier du premier au dernier trait, sans motif trop chargé.</p> <h3>✅ Le cadeau qui fait toujours plaisir</h3> <p>Pour soi ou à offrir : un objet doux, accessible et personnel qui plaît aux ados comme aux adultes.</p> <h3>📦 Caractéristiques</h3> <ul> <li><strong>Type :</strong> Livre de coloriage broché</li> <li><strong>Pages :</strong> 28 pages</li> <li><strong>Papier :</strong> Épais, adapté aux feutres et crayons</li> <li><strong>Format :</strong> Compact, transportable</li> <li><strong>Contenu :</strong> 1 livre de coloriage</li> </ul> <h3>❓ Questions fréquentes</h3> <details><summary>Le papier bave-t-il avec les feutres ?</summary><p>Le papier est épais ; pour les feutres à alcool, glissez une feuille sous la page en cours par précaution.</p></details> <details><summary>Convient-il aux débutants ?</summary><p>Oui, les motifs sont accessibles : aucune technique requise, juste l'envie de colorier.</p></details> <details><summary>Y a-t-il du texte à l'intérieur ?</summary><p>Ce sont des pages à colorier ; le texte est minimal, l'univers est visuel.</p></details> <p><strong>🛒 Offrez-vous cette pause — Livraison offerte dès 39€ d'achat.</strong></p> </div>
A8: coloriage-kawaii-5 | B8: coloriage kawaii | C8: Livre de coloriage Cat Moments (adulte, chats) | D8: https://fr.aliexpress.com/item/1005009054606907.html | E8: 6.89 | F8: 0 | G8: =IF(OR(E8="",F8=""),"",E8+F8) | H8: =IFERROR(VLOOKUP(B8,'Collections'!$C$4:$L$18,10,FALSE),"") | I8: =IFERROR(H8/G8,"") | J8: 4.9 | K8: 5000 | L8: Choice — vendeur agrégé | M8: 16-19 juil. (~6-9 j) | N8: Choice | O8: style 13 | P8: Pour amoureux des chats — coloriage relaxation, papier épais | Q8: Livre papier, visuels chats génériques (OK licence). Vérifier texte intérieur minimal. Marge x3,6. | R8: Retenir | S8: 46213 | T8: AliExpress Choice ; livraison gratuite dès 10€ ; 914 avis ; note agrégée | U8: PACKSHOT — E-commerce hero packshot of the coloring book «Livre de coloriage Cat Moments (adulte, chats)», cover facing forward, centered on a clean seamless pastel background, soft studio shadow, ultra-sharp, soft pastel kawaii brand aesthetic, cohesive palette (blush pink, cream, mint, lilac), 1:1 square. LIFESTYLE — Top-down flat-lay of «Livre de coloriage Cat Moments (adulte, chats)» on a cozy pastel desk with colored pencils, a warm drink and a small plush, soft natural morning light, hygge kawaii mood, soft pastel kawaii brand aesthetic, cohesive palette (blush pink, cream, mint, lilac), 1:1. EN SITUATION — Close-up of a person's hands coloring a kawaii page from «Livre de coloriage Cat Moments (adulte, chats)», cozy blanket, shallow depth of field, warm soft tones. DÉTAIL — Macro of the open inner pages of «Livre de coloriage Cat Moments (adulte, chats)» showing cute kawaii line-art illustrations, crisp lines, shallow depth of field. FEATURE — Clean product feature image of «Livre de coloriage Cat Moments (adulte, chats)» standing upright with minimal text callouts (page count, thick paper, anti-stress), soft pastel kawaii brand aesthetic, cohesive palette (blush pink, cream, mint, lilac), generous negative space for headline. | V8: .../outputs/coloriage-kawaii-arborescence-2026-07-09/images_produits/08_coloriage-kawaii_1005009054606907 | W8: Coloriage kawaii Cat Moments (adulte, chats) | [Marque] | X8: Cat Moments (adulte, chats) — coloriage kawaii | [Marque] | Y8: Cat Moments (adulte, chats) : détente kawaii, illustrations mignonnes. Livraison rapide, avis vérifiés. Commandez sur [Marque] ! | Z8: <div class="product-desc"> <p>Coloriage kawaii <strong>« Cat Moments (adulte, chats) »</strong> — détente kawaii, illustrations mignonnes.</p> <p><strong>Et si 15 minutes de coloriage remplaçaient le scroll du soir ?</strong></p> <h3>✅ Une vraie parenthèse détente</h3> <p>Ce livre de kawaii aide à relâcher la pression : on se concentre sur les couleurs, le mental se pose. Idéal le soir ou le week-end.</p> <h3>✅ Des illustrations originales et mignonnes</h3> <p>Des pages au style kawaii, pensées pour être agréables à colorier du premier au dernier trait, sans motif trop chargé.</p> <h3>✅ Le cadeau qui fait toujours plaisir</h3> <p>Pour soi ou à offrir : un objet doux, accessible et personnel qui plaît aux ados comme aux adultes.</p> <h3>📦 Caractéristiques</h3> <ul> <li><strong>Type :</strong> Livre de coloriage broché</li> <li><strong>Pages :</strong> ≈ 24-30 pages</li> <li><strong>Papier :</strong> Épais, adapté aux feutres et crayons</li> <li><strong>Format :</strong> Compact, transportable</li> <li><strong>Contenu :</strong> 1 livre de coloriage</li> </ul> <h3>❓ Questions fréquentes</h3> <details><summary>Le papier bave-t-il avec les feutres ?</summary><p>Le papier est épais ; pour les feutres à alcool, glissez une feuille sous la page en cours par précaution.</p></details> <details><summary>Convient-il aux débutants ?</summary><p>Oui, les motifs sont accessibles : aucune technique requise, juste l'envie de colorier.</p></details> <details><summary>Y a-t-il du texte à l'intérieur ?</summary><p>Ce sont des pages à colorier ; le texte est minimal, l'univers est visuel.</p></details> <p><strong>🛒 Offrez-vous cette pause — Livraison offerte dès 39€ d'achat.</strong></p> </div>
